Workbook

Sheet Dashboard

Sheet KPIs
A1: Total Sales: | C1: Total Orders: | E1: Total Customers: | G1: Total Coffee Sold:
A2: =SUM(Orders_Table[Sales]) -> 45134.255 | C2: =COUNTA(Orders!A:A)-1 -> 1000 | E2: =COUNTA(_xlfn.UNIQUE(Orders!F:F))-1 -> 914 | G2: =SUM(Orders!H:H)-1 -> 3550

Sheet QuantityofSizes
A3: Size | B3: Sum of Quantity
A4: 0.2 | B4: 892
A5: 0.5 | B5: 943
A6: 1 | B6: 875
A7: 2.5 | B7: 841

Sheet SalesbyRoastType 
A3: Roast Type Full | B3: Sum of Sales
A4: Dark | B4: 13179.315
A5: Light | B5: 17354.465
A6: Medium | B6: 14600.475

Sheet SalesbyCoffeeType
A3: Coffee Name | B3: Sum of Sales
A4: Arabica | B4: 11768.495
A5: Excelsa | B5: 12306.44
A6: Liberica | B6: 12054.075
A7: Robusta | B7: 9005.245

Sheet SalesByCountry
A3: Country | B3: Sum of Sales
A4: Ireland | B4: 6439.575
A5: United Kingdom | B5: 2593.225
A6: United States | B6: 34281.25

Sheet TotalSales
A3: Sum of Sales | C3: Coffee Name
A4: Year | B4: Month | C4: Arabica | D4: Excelsa | E4: Liberica | F4: Robusta
A5: 2019 | B5: Jan | C5: 186.855 | D5: 305.97 | E5: 213.16 | F5: 123
B6: Feb | C6: 251.965 | D6: 129.46 | E6: 434.04 | F6: 171.94
B7: Mar | C7: 224.945 | D7: 349.12 | E7: 321.04 | F7: 126.035
B8: Apr | C8: 307.12 | D8: 681.075 | E8: 533.705 | F8: 158.85
B9: May | C9: 53.665 | D9: 83.025 | E9: 193.835 | F9: 68.04
B10: Jun | C10: 163.02 | D10: 678.36 | E10: 171.045 | F10: 372.255
B11: Jul | C11: 345.02 | D11: 273.87 | E11: 184.13 | F11: 201.115
B12: Aug | C12: 334.89 | D12: 70.95 | E12: 134.23 | F12: 166.275
B13: Sep | C13: 178.71 | D13: 166.1 | E13: 439.31 | F13: 492.9
B14: Oct | C14: 301.985 | D14: 153.765 | E14: 215.555 | F14: 213.665
B15: Nov | C15: 312.835 | D15: 63.25 | E15: 350.895 | F15: 96.405
B16: Dec | C16: 265.62 | D16: 526.515 | E16: 187.06 | F16: 210.59
A17: 2020 | B17: Jan | C17: 47.25 | D17: 65.805 | E17: 274.675 | F17: 179.22
B18: Feb | C18: 745.45 | D18: 428.885 | E18: 194.175 | F18: 429.83
B19: Mar | C19: 130.47 | D19: 271.485 | E19: 281.205 | F19: 231.63
B20: Apr | C20: 27 | D20: 347.26 | E20: 147.51 | F20: 240.04
B21: May | C21: 255.115 | D21: 541.73 | E21: 83.43 | F21: 59.08
B22: Jun | C22: 584.79 | D22: 357.43 | E22: 355.34 | F22: 140.88
B23: Jul | C23: 430.62 | D23: 227.425 | E23: 236.315 | F23: 414.585
B24: Aug | C24: 22.5 | D24: 77.72 | E24: 60.5 | F24: 139.68
B25: Sep | C25: 126.15 | D25: 195.11 | E25: 89.13 | F25: 302.66
B26: Oct | C26: 376.03 | D26: 523.24 | E26: 440.965 | F26: 174.47
B27: Nov | C27: 515.18 | D27: 142.56 | E27: 347.04 | F27: 104.085
B28: Dec | C28: 95.86 | D28: 484.76 | E28: 94.17 | F28: 77.105
A29: 2021 | B29: Jan | C29: 258.345 | D29: 139.625 | E29: 279.52 | F29: 160.195
B30: Feb | C30: 342.2 | D30: 284.25 | E30: 251.83 | F30: 80.55
B31: Mar | C31: 418.305 | D31: 468.125 | E31: 405.055 | F31: 253.155
B32: Apr | C32: 102.33 | D32: 242.14 | E32: 554.875 | F32: 106.24
B33: May | C33: 234.72 | D33: 133.08 | E33: 267.2 | F33: 272.69
B34: Jun | C34: 430.39 | D34: 136.205 | E34: 209.6 | F34: 88.335
B35: Jul | C35: 109.005 | D35: 393.575 | E35: 61.035 | F35: 199.49
B36: Aug | C36: 287.525 | D36: 288.67 | E36: 125.58 | F36: 374.135
B37: Sep | C37: 840.93 | D37: 409.875 | E37: 171.33 | F37: 221.44
B38: Oct | C38: 299.07 | D38: 260.325 | E38: 584.64 | F38: 256.365
B39: Nov | C39: 323.325 | D39: 565.57 | E39: 537.81 | F39: 189.475
B40: Dec | C40: 399.485 | D40: 148.2 | E40: 388.22 | F40: 212.075
A41: 2022 | B41: Jan | C41: 112.695 | D41: 166.32 | E41: 843.715 | F41: 146.685
B42: Feb | C42: 114.88 | D42: 133.815 | E42: 91.175 | F42: 53.76
...

Sheet Orders
A1: Order ID | B1: Order Date | C1: Year | D1: Month Number | E1: Month | F1: Customer ID | G1: Product ID | H1: Quantity | I1: Customer Name | J1: Email | K1: Country | L1: Coffee Type | M1: Roast Type | N1: Size | O1: Unit Price | P1: Sales | Q1: Coffee Type Full | R1: Roast Type Full
A2: QEV-37451-860 | B2: 43713 | C2: =YEAR(Orders_Table[[#This Row],[Order Date]]) -> 2019 | D2: =MONTH(Orders_Table[[#This Row],[Order Date]]) -> 9 | E2: {=_xlfn.IFS(Orders_Table[[#This Row],[Month Number]]=1,"Jan",Orders_Table[[#This Row],[Month Number]]=2,"Feb",Orders_Table[[#This Row],[Month Number]]=3,"Mar",Orders_Table[[#This Row],[Month Number]]=4,"Apr",Orders_Table[[#This Row],[Month Number]]=5,"May",Orders_Table[[#This Row],[Month Number]]=6,"Jun",Orders_Table[[#This Row],[Month Number]]=7,"Jul",Orders_Table[[#This Row],[Month Number]]=8,"Aug",Orders_Table[[#This Row],[Month Number]]=9,"Sep",Orders_Table[[#This Row],[Month Number]]=10,"Oct",Orders_Table[[#This Row],[Month Number]]=11,"Nov",Orders_Table[[#This Row],[Month Number]]=12,"Dec")} -> Sep | F2: 17670-51384-MA | G2: R-M-1 | H2: 2 | I2: {=_xlfn.XLOOKUP(F2,Customers!A1:$A$1001,Customers!B1:$B$1001,"Not Found",0)} -> Aloisia Allner | J2: {=IF(_xlfn.XLOOKUP(F2,Customers!A1:$A$1001,Customers!C1:$C$1001,"Not Found",0)=0,"",_xlfn.XLOOKUP(F2,Customers!A1:$A$1001,Customers!C1:$C$1001,"Not Found",0))} -> aallner0@lulu.com | K2: {=_xlfn.XLOOKUP(F2,Customers!A1:$A$1001,Customers!G1:$G$1001,"Not Found",0)} -> United States | L2: =INDEX(Products!$A$1:$G$49,MATCH(Orders!$G2,Products!$A$1:$A$49,0),MATCH(Orders!L$1,Products!$A$1:$G$1,0)) -> Rob | M2: =INDEX(Products!$A$1:$G$49,MATCH(Orders!$G2,Products!$A$1:$A$49,0),MATCH(Orders!M$1,Products!$A$1:$G$1,0)) -> M | N2: =INDEX(Products!$A$1:$G$49,MATCH(Orders!$G2,Products!$A$1:$A$49,0),MATCH(Orders!N$1,Products!$A$1:$G$1,0)) -> 1 | O2: =INDEX(Products!$A$1:$G$49,MATCH(Orders!$G2,Products!$A$1:$A$49,0),MATCH(Orders!O$1,Products!$A$1:$G$1,0)) -> 9.95 | P2: =O2*H2 -> 19.9 | Q2: {=_xlfn.IFS(L2="Rob","Robusta",L2="Exc", "Excelsa",L2="Ara", "Arabica",L2="Lib", "Liberica")} -> Robusta | R2: {=_xlfn.IFS(M2="M","Medium",M2="L","Light",M2="D","Dark")} -> Medium
A3: QEV-37451-860 | B3: 43713 | C3: =YEAR(Orders_Table[[#This Row],[Order Date]]) -> 2019 | D3: =MONTH(Orders_Table[[#This Row],[Order Date]]) -> 9 | E3: {=_xlfn.IFS(Orders_Table[[#This Row],[Month Number]]=1,"Jan",Orders_Table[[#This Row],[Month Number]]=2,"Feb",Orders_Table[[#This Row],[Month Number]]=3,"Mar",Orders_Table[[#This Row],[Month Number]]=4,"Apr",Orders_Table[[#This Row],[Month Number]]=5,"May",Orders_Table[[#This Row],[Month Number]]=6,"Jun",Orders_Table[[#This Row],[Month Number]]=7,"Jul",Orders_Table[[#This Row],[Month Number]]=8,"Aug",Orders_Table[[#This Row],[Month Number]]=9,"Sep",Orders_Table[[#This Row],[Month Number]]=10,"Oct",Orders_Table[[#This Row],[Month Number]]=11,"Nov",Orders_Table[[#This Row],[Month Number]]=12,"Dec")} -> Sep | F3: 17670-51384-MA | G3: E-M-0.5 | H3: 5 | I3: {=_xlfn.XLOOKUP(F3,Customers!A2:$A$1001,Customers!B2:$B$1001,"Not Found",0)} -> Aloisia Allner | J3: {=IF(_xlfn.XLOOKUP(F3,Customers!A2:$A$1001,Customers!C2:$C$1001,"Not Found",0)=0,"",_xlfn.XLOOKUP(F3,Customers!A2:$A$1001,Customers!C2:$C$1001,"Not Found",0))} -> aallner0@lulu.com | K3: {=_xlfn.XLOOKUP(F3,Customers!A2:$A$1001,Customers!G2:$G$1001,"Not Found",0)} -> United States | L3: =INDEX(Products!$A$1:$G$49,MATCH(Orders!$G3,Products!$A$1:$A$49,0),MATCH(Orders!L$1,Products!$A$1:$G$1,0)) -> Exc | M3: =INDEX(Products!$A$1:$G$49,MATCH(Orders!$G3,Products!$A$1:$A$49,0),MATCH(Orders!M$1,Products!$A$1:$G$1,0)) -> M | N3: =INDEX(Products!$A$1:$G$49,MATCH(Orders!$G3,Products!$A$1:$A$49,0),MATCH(Orders!N$1,Products!$A$1:$G$1,0)) -> 0.5 | O3: =INDEX(Products!$A$1:$G$49,MATCH(Orders!$G3,Products!$A$1:$A$49,0),MATCH(Orders!O$1,Products!$A$1:$G$1,0)) -> 8.25 | P3: =O3*H3 -> 41.25 | Q3: {=_xlfn.IFS(L3="Rob","Robusta",L3="Exc", "Excelsa",L3="Ara", "Arabica",L3="Lib", "Liberica")} -> Excelsa | R3: {=_xlfn.IFS(M3="M","Medium",M3="L","Light",M3="D","Dark")} -> Medium
A4: FAA-43335-268 | B4: 44364 | C4: =YEAR(Orders_Table[[#This Row],[Order Date]]) -> 2021 | D4: =MONTH(Orders_Table[[#This Row],[Order Date]]) -> 6 | E4: {=_xlfn.IFS(Orders_Table[[#This Row],[Month Number]]=1,"Jan",Orders_Table[[#This Row],[Month Number]]=2,"Feb",Orders_Table[[#This Row],[Month Number]]=3,"Mar",Orders_Table[[#This Row],[Month Number]]=4,"Apr",Orders_Table[[#This Row],[Month Number]]=5,"May",Orders_Table[[#This Row],[Month Number]]=6,"Jun",Orders_Table[[#This Row],[Month Number]]=7,"Jul",Orders_Table[[#This Row],[Month Number]]=8,"Aug",Orders_Table[[#This Row],[Month Number]]=9,"Sep",Orders_Table[[#This Row],[Month Number]]=10,"Oct",Orders_Table[[#This Row],[Month Number]]=11,"Nov",Orders_Table[[#This Row],[Month Number]]=12,"Dec")} -> Jun | F4: 21125-22134-PX | G4: A-L-1 | H4: 1 | I4: {=_xlfn.XLOOKUP(F4,Customers!A3:$A$1001,Customers!B3:$B$1001,"Not Found",0)} -> Jami Redholes | J4: {=IF(_xlfn.XLOOKUP(F4,Customers!A3:$A$1001,Customers!C3:$C$1001,"Not Found",0)=0,"",_xlfn.XLOOKUP(F4,Customers!A3:$A$1001,Customers!C3:$C$1001,"Not Found",0))} -> jredholes2@tmall.com | K4: {=_xlfn.XLOOKUP(F4,Customers!A3:$A$1001,Customers!G3:$G$1001,"Not Found",0)} -> United States | L4: =INDEX(Products!$A$1:$G$49,MATCH(Orders!$G4,Products!$A$1:$A$49,0),MATCH(Orders!L$1,Products!$A$1:$G$1,0)) -> Ara | M4: =INDEX(Products!$A$1:$G$49,MATCH(Orders!$G4,Products!$A$1:$A$49,0),MATCH(Orders!M$1,Products!$A$1:$G$1,0)) -> L | N4: =INDEX(Products!$A$1:$G$49,MATCH(Orders!$G4,Products!$A$1:$A$49,0),MATCH(Orders!N$1,Products!$A$1:$G$1,0)) -> 1 | O4: =INDEX(Products!$A$1:$G$49,MATCH(Orders!$G4,Products!$A$1:$A$49,0),MATCH(Orders!O$1,Products!$A$1:$G$1,0)) -> 12.95 | P4: =O4*H4 -> 12.95 | Q4: {=_xlfn.IFS(L4="Rob","Robusta",L4="Exc", "Excelsa",L4="Ara", "Arabica",L4="Lib", "Liberica")} -> Arabica | R4: {=_xlfn.IFS(M4="M","Medium",M4="L","Light",M4="D","Dark")} -> Light
A5: KAC-83089-793 | B5: 44392 | C5: =YEAR(Orders_Table[[#This Row],[Order Date]]) -> 2021 | D5: =MONTH(Orders_Table[[#This Row],[Order Date]]) -> 7 | E5: {=_xlfn.IFS(Orders_Table[[#This Row],[Month Number]]=1,"Jan",Orders_Table[[#This Row],[Month Number]]=2,"Feb",Orders_Table[[#This Row],[Month Number]]=3,"Mar",Orders_Table[[#This Row],[Month Number]]=4,"Apr",Orders_Table[[#This Row],[Month Number]]=5,"May",Orders_Table[[#This Row],[Month Number]]=6,"Jun",Orders_Table[[#This Row],[Month Number]]=7,"Jul",Orders_Table[[#This Row],[Month Number]]=8,"Aug",Orders_Table[[#This Row],[Month Number]]=9,"Sep",Orders_Table[[#This Row],[Month Number]]=10,"Oct",Orders_Table[[#This Row],[Month Number]]=11,"Nov",Orders_Table[[#This Row],[Month Number]]=12,"Dec")} -> Jul | F5: 23806-46781-OU | G5: E-M-1 | H5: 2 | I5: {=_xlfn.XLOOKUP(F5,Customers!A4:$A$1001,Customers!B4:$B$1001,"Not Found",0)} -> Christoffer O' Shea | J5: {=IF(_xlfn.XLOOKUP(F5,Customers!A4:$A$1001,Customers!C4:$C$1001,"Not Found",0)=0,"",_xlfn.XLOOKUP(F5,Customers!A4:$A$1001,Customers!C4:$C$1001,"Not Found",0))} | K5: {=_xlfn.XLOOKUP(F5,Customers!A4:$A$1001,Customers!G4:$G$1001,"Not Found",0)} -> Ireland | L5: =INDEX(Products!$A$1:$G$49,MATCH(Orders!$G5,Products!$A$1:$A$49,0),MATCH(Orders!L$1,Products!$A$1:$G$1,0)) -> Exc | M5: =INDEX(Products!$A$1:$G$49,MATCH(Orders!$G5,Products!$A$1:$A$49,0),MATCH(Orders!M$1,Products!$A$1:$G$1,0)) -> M | N5: =INDEX(Products!$A$1:$G$49,MATCH(Orders!$G5,Products!$A$1:$A$49,0),MATCH(Orders!N$1,Products!$A$1:$G$1,0)) -> 1 | O5: =INDEX(Products!$A$1:$G$49,MATCH(Orders!$G5,Products!$A$1:$A$49,0),MATCH(Orders!O$1,Products!$A$1:$G$1,0)) -> 13.75 | P5: =O5*H5 -> 27.5 | Q5: {=_xlfn.IFS(L5="Rob","Robusta",L5="Exc", "Excelsa",L5="Ara", "Arabica",L5="Lib", "Liberica")} -> Excelsa | R5: {=_xlfn.IFS(M5="M","Medium",M5="L","Light",M5="D","Dark")} -> Medium
A6: KAC-83089-793 | B6: 44392 | C6: =YEAR(Orders_Table[[#This Row],[Order Date]]) -> 2021 | D6: =MONTH(Orders_Table[[#This Row],[Order Date]]) -> 7 | E6: {=_xlfn.IFS(Orders_Table[[#This Row],[Month Number]]=1,"Jan",Orders_Table[[#This Row],[Month Number]]=2,"Feb",Orders_Table[[#This Row],[Month Number]]=3,"Mar",Orders_Table[[#This Row],[Month Number]]=4,"Apr",Orders_Table[[#This Row],[Month Number]]=5,"May",Orders_Table[[#This Row],[Month Number]]=6,"Jun",Orders_Table[[#This Row],[Month Number]]=7,"Jul",Orders_Table[[#This Row],[Month Number]]=8,"Aug",Orders_Table[[#This Row],[Month Number]]=9,"Sep",Orders_Table[[#This Row],[Month Number]]=10,"Oct",Orders_Table[[#This Row],[Month Number]]=11,"Nov",Orders_Table[[#This Row],[Month Number]]=12,"Dec")} -> Jul | F6: 23806-46781-OU | G6: R-L-2.5 | H6: 2 | I6: {=_xlfn.XLOOKUP(F6,Customers!A5:$A$1001,Customers!B5:$B$1001,"Not Found",0)} -> Christoffer O' Shea | J6: {=IF(_xlfn.XLOOKUP(F6,Customers!A5:$A$1001,Customers!C5:$C$1001,"Not Found",0)=0,"",_xlfn.XLOOKUP(F6,Customers!A5:$A$1001,Customers!C5:$C$1001,"Not Found",0))} | K6: {=_xlfn.XLOOKUP(F6,Customers!A5:$A$1001,Customers!G5:$G$1001,"Not Found",0)} -> Ireland | L6: =INDEX(Products!$A$1:$G$49,MATCH(Orders!$G6,Products!$A$1:$A$49,0),MATCH(Orders!L$1,Products!$A$1:$G$1,0)) -> Rob | M6: =INDEX(Products!$A$1:$G$49,MATCH(Orders!$G6,Products!$A$1:$A$49,0),MATCH(Orders!M$1,Products!$A$1:$G$1,0)) -> L | N6: =INDEX(Products!$A$1:$G$49,MATCH(Orders!$G6,Products!$A$1:$A$49,0),MATCH(Orders!N$1,Products!$A$1:$G$1,0)) -> 2.5 | O6: =INDEX(Products!$A$1:$G$49,MATCH(Orders!$G6,Products!$A$1:$A$49,0),MATCH(Orders!O$1,Products!$A$1:$G$1,0)) -> 27.485 | P6: =O6*H6 -> 54.97 | Q6: {=_xlfn.IFS(L6="Rob","Robusta",L6="Exc", "Excelsa",L6="Ara", "Arabica",L6="Lib", "Liberica")} -> Robusta | R6: {=_xlfn.IFS(M6="M","Medium",M6="L","Light",M6="D","Dark")} -> Light
A7: CVP-18956-553 | B7: 44412 | C7: =YEAR(Orders_Table[[#This Row],[Order Date]]) -> 2021 | D7: =MONTH(Orders_Table[[#This Row],[Order Date]]) -> 8 | E7: {=_xlfn.IFS(Orders_Table[[#This Row],[Month Number]]=1,"Jan",Orders_Table[[#This Row],[Month Number]]=2,"Feb",Orders_Table[[#This Row],[Month Number]]=3,"Mar",Orders_Table[[#This Row],[Month Number]]=4,"Apr",Orders_Table[[#This Row],[Month Number]]=5,"May",Orders_Table[[#This Row],[Month Number]]=6,"Jun",Orders_Table[[#This Row],[Month Number]]=7,"Jul",Orders_Table[[#This Row],[Month Number]]=8,"Aug",Orders_Table[[#This Row],[Month Number]]=9,"Sep",Orders_Table[[#This Row],[Month Number]]=10,"Oct",Orders_Table[[#This Row],[Month Number]]=11,"Nov",Orders_Table[[#This Row],[Month Number]]=12,"Dec")} -> Aug | F7: 86561-91660-RB | G7: L-D-1 | H7: 3 | I7: {=_xlfn.XLOOKUP(F7,Customers!A6:$A$1001,Customers!B6:$B$1001,"Not Found",0)} -> Beryle Cottier | J7: {=IF(_xlfn.XLOOKUP(F7,Customers!A6:$A$1001,Customers!C6:$C$1001,"Not Found",0)=0,"",_xlfn.XLOOKUP(F7,Customers!A6:$A$1001,Customers!C6:$C$1001,"Not Found",0))} | K7: {=_xlfn.XLOOKUP(F7,Customers!A6:$A$1001,Customers!G6:$G$1001,"Not Found",0)} -> United States | L7: =INDEX(Products!$A$1:$G$49,MATCH(Orders!$G7,Products!$A$1:$A$49,0),MATCH(Orders!L$1,Products!$A$1:$G$1,0)) -> Lib | M7: =INDEX(Products!$A$1:$G$49,MATCH(Orders!$G7,Products!$A$1:$A$49,0),MATCH(Orders!M$1,Products!$A$1:$G$1,0)) -> D | N7: =INDEX(Products!$A$1:$G$49,MATCH(Orders!$G7,Products!$A$1:$A$49,0),MATCH(Orders!N$1,Products!$A$1:$G$1,0)) -> 1 | O7: =INDEX(Products!$A$1:$G$49,MATCH(Orders!$G7,Products!$A$1:$A$49,0),MATCH(Orders!O$1,Products!$A$1:$G$1,0)) -> 12.95 | P7: =O7*H7 -> 38.85 | Q7: {=_xlfn.IFS(L7="Rob","Robusta",L7="Exc", "Excelsa",L7="Ara", "Arabica",L7="Lib", "Liberica")} -> Liberica | R7: {=_xlfn.IFS(M7="M","Medium",M7="L","Light",M7="D","Dark")} -> Dark
A8: IPP-31994-879 | B8: 44582 | C8: =YEAR(Orders_Table[[#This Row],[Order Date]]) -> 2022 | D8: =MONTH(Orders_Table[[#This Row],[Order Date]]) -> 1 | E8: {=_xlfn.IFS(Orders_Table[[#This Row],[Month Number]]=1,"Jan",Orders_Table[[#This Row],[Month Number]]=2,"Feb",Orders_Table[[#This Row],[Month Number]]=3,"Mar",Orders_Table[[#This Row],[Month Number]]=4,"Apr",Orders_Table[[#This Row],[Month Number]]=5,"May",Orders_Table[[#This Row],[Month Number]]=6,"Jun",Orders_Table[[#This Row],[Month Number]]=7,"Jul",Orders_Table[[#This Row],[Month Number]]=8,"Aug",Orders_Table[[#This Row],[Month Number]]=9,"Sep",Orders_Table[[#This Row],[Month Number]]=10,"Oct",Orders_Table[[#This Row],[Month Number]]=11,"Nov",Orders_Table[[#This Row],[Month Number]]=12,"Dec")} -> Jan | F8: 65223-29612-CB | G8: E-D-0.5 | H8: 3 | I8: {=_xlfn.XLOOKUP(F8,Customers!A7:$A$1001,Customers!B7:$B$1001,"Not Found",0)} -> Shaylynn Lobe | J8: {=IF(_xlfn.XLOOKUP(F8,Customers!A7:$A$1001,Customers!C7:$C$1001,"Not Found",0)=0,"",_xlfn.XLOOKUP(F8,Customers!A7:$A$1001,Customers!C7:$C$1001,"Not Found",0))} -> slobe6@nifty.com | K8: {=_xlfn.XLOOKUP(F8,Customers!A7:$A$1001,Customers!G7:$G$1001,"Not Found",0)} -> United States | L8: =INDEX(Products!$A$1:$G$49,MATCH(Orders!$G8,Products!$A$1:$A$49,0),MATCH(Orders!L$1,Products!$A$1:$G$1,0)) -> Exc | M8: =INDEX(Products!$A$1:$G$49,MATCH(Orders!$G8,Products!$A$1:$A$49,0),MATCH(Orders!M$1,Products!$A$1:$G$1,0)) -> D | N8: =INDEX(Products!$A$1:$G$49,MATCH(Orders!$G8,Products!$A$1:$A$49,0),MATCH(Orders!N$1,Products!$A$1:$G$1,0)) -> 0.5 | O8: =INDEX(Products!$A$1:$G$49,MATCH(Orders!$G8,Products!$A$1:$A$49,0),MATCH(Orders!O$1,Products!$A$1:$G$1,0)) -> 7.29 | P8: =O8*H8 -> 21.87 | Q8: {=_xlfn.IFS(L8="Rob","Robusta",L8="Exc", "Excelsa",L8="Ara", "Arabica",L8="Lib", "Liberica")} -> Excelsa | R8: {=_xlfn.IFS(M8="M","Medium",M8="L","Light",M8="D","Dark")} -> Dark
A9: SNZ-65340-705 | B9: 44701 | C9: =YEAR(Orders_Table[[#This Row],[Order Date]]) -> 2022 | D9: =MONTH(Orders_Table[[#This Row],[Order Date]]) -> 5 | E9: {=_xlfn.IFS(Orders_Table[[#This Row],[Month Number]]=1,"Jan",Orders_Table[[#This Row],[Month Number]]=2,"Feb",Orders_Table[[#This Row],[Month Number]]=3,"Mar",Orders_Table[[#This Row],[Month Number]]=4,"Apr",Orders_Table[[#This Row],[Month Number]]=5,"May",Orders_Table[[#This Row],[Month Number]]=6,"Jun",Orders_Table[[#This Row],[Month Number]]=7,"Jul",Orders_Table[[#This Row],[Month Number]]=8,"Aug",Orders_Table[[#This Row],[Month Number]]=9,"Sep",Orders_Table[[#This Row],[Month Number]]=10,"Oct",Orders_Table[[#This Row],[Month Number]]=11,"Nov",Orders_Table[[#This Row],[Month Number]]=12,"Dec")} -> May | F9: 21134-81676-FR | G9: L-L-0.2 | H9: 1 | I9: {=_xlfn.XLOOKUP(F9,Customers!A8:$A$1001,Customers!B8:$B$1001,"Not Found",0)} -> Melvin Wharfe | J9: {=IF(_xlfn.XLOOKUP(F9,Customers!A8:$A$1001,Customers!C8:$C$1001,"Not Found",0)=0,"",_xlfn.XLOOKUP(F9,Customers!A8:$A$1001,Customers!C8:$C$1001,"Not Found",0))} | K9: {=_xlfn.XLOOKUP(F9,Customers!A8:$A$1001,Customers!G8:$G$1001,"Not Found",0)} -> Ireland | L9: =INDEX(Products!$A$1:$G$49,MATCH(Orders!$G9,Products!$A$1:$A$49,0),MATCH(Orders!L$1,Products!$A$1:$G$1,0)) -> Lib | M9: =INDEX(Products!$A$1:$G$49,MATCH(Orders!$G9,Products!$A$1:$A$49,0),MATCH(Orders!M$1,Products!$A$1:$G$1,0)) -> L | N9: =INDEX(Products!$A$1:$G$49,MATCH(Orders!$G9,Products!$A$1:$A$49,0),MATCH(Orders!N$1,Products!$A$1:$G$1,0)) -> 0.2 | O9: =INDEX(Products!$A$1:$G$49,MATCH(Orders!$G9,Products!$A$1:$A$49,0),MATCH(Orders!O$1,Products!$A$1:$G$1,0)) -> 4.755 | P9: =O9*H9 -> 4.755 | Q9: {=_xlfn.IFS(L9="Rob","Robusta",L9="Exc", "Excelsa",L9="Ara", "Arabica",L9="Lib", "Liberica")} -> Liberica | R9: {=_xlfn.IFS(M9="M","Medium",M9="L","Light",M9="D","Dark")} -> Light
A10: EZT-46571-659 | B10: 43467 | C10: =YEAR(Orders_Table[[#This Row],[Order Date]]) -> 2019 | D10: =MONTH(Orders_Table[[#This Row],[Order Date]]) -> 1 | E10: {=_xlfn.IFS(Orders_Table[[#This Row],[Month Number]]=1,"Jan",Orders_Table[[#This Row],[Month Number]]=2,"Feb",Orders_Table[[#This Row],[Month Number]]=3,"Mar",Orders_Table[[#This Row],[Month Number]]=4,"Apr",Orders_Table[[#This Row],[Month Number]]=5,"May",Orders_Table[[#This Row],[Month Number]]=6,"Jun",Orders_Table[[#This Row],[Month Number]]=7,"Jul",Orders_Table[[#This Row],[Month Number]]=8,"Aug",Orders_Table[[#This Row],[Month Number]]=9,"Sep",Orders_Table[[#This Row],[Month Number]]=10,"Oct",Orders_Table[[#This Row],[Month Number]]=11,"Nov",Orders_Table[[#This Row],[Month Number]]=12,"Dec")} -> Jan | F10: 03396-68805-ZC | G10: R-M-0.5 | H10: 3 | I10: {=_xlfn.XLOOKUP(F10,Customers!A9:$A$1001,Customers!B9:$B$1001,"Not Found",0)} -> Guthrey Petracci | J10: {=IF(_xlfn.XLOOKUP(F10,Customers!A9:$A$1001,Customers!C9:$C$1001,"Not Found",0)=0,"",_xlfn.XLOOKUP(F10,Customers!A9:$A$1001,Customers!C9:$C$1001,"Not Found",0))} -> gpetracci8@livejournal.com | K10: {=_xlfn.XLOOKUP(F10,Customers!A9:$A$1001,Customers!G9:$G$1001,"Not Found",0)} -> United States | L10: =INDEX(Products!$A$1:$G$49,MATCH(Orders!$G10,Products!$A$1:$A$49,0),MATCH(Orders!L$1,Products!$A$1:$G$1,0)) -> Rob | M10: =INDEX(Products!$A$1:$G$49,MATCH(Orders!$G10,Products!$A$1:$A$49,0),MATCH(Orders!M$1,Products!$A$1:$G$1,0)) -> M | N10: =INDEX(Products!$A$1:$G$49,MATCH(Orders!$G10,Products!$A$1:$A$49,0),MATCH(Orders!N$1,Products!$A$1:$G$1,0)) -> 0.5 | O10: =INDEX(Products!$A$1:$G$49,MATCH(Orders!$G10,Products!$A$1:$A$49,0),MATCH(Orders!O$1,Products!$A$1:$G$1,0)) -> 5.97 | P10: =O10*H10 -> 17.91 | Q10: {=_xlfn.IFS(L10="Rob","Robusta",L10="Exc", "Excelsa",L10="Ara", "Arabica",L10="Lib", "Liberica")} -> Robusta | R10: {=_xlfn.IFS(M10="M","Medium",M10="L","Light",M10="D","Dark")} -> Medium
A11: NWQ-70061-912 | B11: 43713 | C11: =YEAR(Orders_Table[[#This Row],[Order Date]]) -> 2019 | D11: =MONTH(Orders_Table[[#This Row],[Order Date]]) -> 9 | E11: {=_xlfn.IFS(Orders_Table[[#This Row],[Month Number]]=1,"Jan",Orders_Table[[#This Row],[Month Number]]=2,"Feb",Orders_Table[[#This Row],[Month Number]]=3,"Mar",Orders_Table[[#This Row],[Month Number]]=4,"Apr",Orders_Table[[#This Row],[Month Number]]=5,"May",Orders_Table[[#This Row],[Month Number]]=6,"Jun",Orders_Table[[#This Row],[Month Number]]=7,"Jul",Orders_Table[[#This Row],[Month Number]]=8,"Aug",Orders_Table[[#This Row],[Month Number]]=9,"Sep",Orders_Table[[#This Row],[Month Number]]=10,"Oct",Orders_Table[[#This Row],[Month Number]]=11,"Nov",Orders_Table[[#This Row],[Month Number]]=12,"Dec")} -> Sep | F11: 61021-27840-ZN | G11: R-M-0.5 | H11: 1 | I11: {=_xlfn.XLOOKUP(F11,Customers!A10:$A$1001,Customers!B10:$B$1001,"Not Found",0)} -> Rodger Raven | J11: {=IF(_xlfn.XLOOKUP(F11,Customers!A10:$A$1001,Customers!C10:$C$1001,"Not Found",0)=0,"",_xlfn.XLOOKUP(F11,Customers!A10:$A$1001,Customers!C10:$C$1001,"Not Found",0))} -> rraven9@ed.gov | K11: {=_xlfn.XLOOKUP(F11,Customers!A10:$A$1001,Customers!G10:$G$1001,"Not Found",0)} -> United States | L11: =INDEX(Products!$A$1:$G$49,MATCH(Orders!$G11,Products!$A$1:$A$49,0),MATCH(Orders!L$1,Products!$A$1:$G$1,0)) -> Rob | M11: =INDEX(Products!$A$1:$G$49,MATCH(Orders!$G11,Products!$A$1:$A$49,0),MATCH(Orders!M$1,Products!$A$1:$G$1,0)) -> M | N11: =INDEX(Products!$A$1:$G$49,MATCH(Orders!$G11,Products!$A$1:$A$49,0),MATCH(Orders!N$1,Products!$A$1:$G$1,0)) -> 0.5 | O11: =INDEX(Products!$A$1:$G$49,MATCH(Orders!$G11,Products!$A$1:$A$49,0),MATCH(Orders!O$1,Products!$A$1:$G$1,0)) -> 5.97 | P11: =O11*H11 -> 5.97 | Q11: {=_xlfn.IFS(L11="Rob","Robusta",L11="Exc", "Excelsa",L11="Ara", "Arabica",L11="Lib", "Liberica")} -> Robusta | R11: {=_xlfn.IFS(M11="M","Medium",M11="L","Light",M11="D","Dark")} -> Medium
A12: BKK-47233-845 | B12: 44263 | C12: =YEAR(Orders_Table[[#This Row],[Order Date]]) -> 2021 | D12: =MONTH(Orders_Table[[#This Row],[Order Date]]) -> 3 | E12: {=_xlfn.IFS(Orders_Table[[#This Row],[Month Number]]=1,"Jan",Orders_Table[[#This Row],[Month Number]]=2,"Feb",Orders_Table[[#This Row],[Month Number]]=3,"Mar",Orders_Table[[#This Row],[Month Number]]=4,"Apr",Orders_Table[[#This Row],[Month Number]]=5,"May",Orders_Table[[#This Row],[Month Number]]=6,"Jun",Orders_Table[[#This Row],[Month Number]]=7,"Jul",Orders_Table[[#This Row],[Month Number]]=8,"Aug",Orders_Table[[#This Row],[Month Number]]=9,"Sep",Orders_Table[[#This Row],[Month Number]]=10,"Oct",Orders_Table[[#This Row],[Month Number]]=11,"Nov",Orders_Table[[#This Row],[Month Number]]=12,"Dec")} -> Mar | F12: 76239-90137-UQ | G12: A-D-1 | H12: 4 | I12: {=_xlfn.XLOOKUP(F12,Customers!A11:$A$1001,Customers!B11:$B$1001,"Not Found",0)} -> Ferrell Ferber | J12: {=IF(_xlfn.XLOOKUP(F12,Customers!A11:$A$1001,Customers!C11:$C$1001,"Not Found",0)=0,"",_xlfn.XLOOKUP(F12,Customers!A11:$A$1001,Customers!C11:$C$1001,"Not Found",0))} -> fferbera@businesswire.com | K12: {=_xlfn.XLOOKUP(F12,Customers!A11:$A$1001,Customers!G11:$G$1001,"Not Found",0)} -> United States | L12: =INDEX(Products!$A$1:$G$49,MATCH(Orders!$G12,Products!$A$1:$A$49,0),MATCH(Orders!L$1,Products!$A$1:$G$1,0)) -> Ara | M12: =INDEX(Products!$A$1:$G$49,MATCH(Orders!$G12,Products!$A$1:$A$49,0),MATCH(Orders!M$1,Products!$A$1:$G$1,0)) -> D | N12: =INDEX(Products!$A$1:$G$49,MATCH(Orders!$G12,Products!$A$1:$A$49,0),MATCH(Orders!N$1,Products!$A$1:$G$1,0)) -> 1 | O12: =INDEX(Products!$A$1:$G$49,MATCH(Orders!$G12,Products!$A$1:$A$49,0),MATCH(Orders!O$1,Products!$A$1:$G$1,0)) -> 9.95 | P12: =O12*H12 -> 39.8 | Q12: {=_xlfn.IFS(L12="Rob","Robusta",L12="Exc", "Excelsa",L12="Ara", "Arabica",L12="Lib", "Liberica")} -> Arabica | R12: {=_xlfn.IFS(M12="M","Medium",M12="L","Light",M12="D","Dark")} -> Dark
A13: VQR-01002-970 | B13: 44132 | C13: =YEAR(Orders_Table[[#This Row],[Order Date]]) -> 2020 | D13: =MONTH(Orders_Table[[#This Row],[Order Date]]) -> 10 | E13: {=_xlfn.IFS(Orders_Table[[#This Row],[Month Number]]=1,"Jan",Orders_Table[[#This Row],[Month Number]]=2,"Feb",Orders_Table[[#This Row],[Month Number]]=3,"Mar",Orders_Table[[#This Row],[Month Number]]=4,"Apr",Orders_Table[[#This Row],[Month Number]]=5,"May",Orders_Table[[#This Row],[Month Number]]=6,"Jun",Orders_Table[[#This Row],[Month Number]]=7,"Jul",Orders_Table[[#This Row],[Month Number]]=8,"Aug",Orders_Table[[#This Row],[Month Number]]=9,"Sep",Orders_Table[[#This Row],[Month Number]]=10,"Oct",Orders_Table[[#This Row],[Month Number]]=11,"Nov",Orders_Table[[#This Row],[Month Number]]=12,"Dec")} -> Oct | F13: 49315-21985-BB | G13: E-L-2.5 | H13: 5 | I13: {=_xlfn.XLOOKUP(F13,Customers!A12:$A$1001,Customers!B12:$B$1001,"Not Found",0)} -> Duky Phizackerly | J13: {=IF(_xlfn.XLOOKUP(F13,Customers!A12:$A$1001,Customers!C12:$C$1001,"Not Found",0)=0,"",_xlfn.XLOOKUP(F13,Customers!A12:$A$1001,Customers!C12:$C$1001,"Not Found",0))} -> dphizackerlyb@utexas.edu | K13: {=_xlfn.XLOOKUP(F13,Customers!A12:$A$1001,Customers!G12:$G$1001,"Not Found",0)} -> United States | L13: =INDEX(Products!$A$1:$G$49,MATCH(Orders!$G13,Products!$A$1:$A$49,0),MATCH(Orders!L$1,Products!$A$1:$G$1,0)) -> Exc | M13: =INDEX(Products!$A$1:$G$49,MATCH(Orders!$G13,Products!$A$1:$A$49,0),MATCH(Orders!M$1,Products!$A$1:$G$1,0)) -> L | N13: =INDEX(Products!$A$1:$G$49,MATCH(Orders!$G13,Products!$A$1:$A$49,0),MATCH(Orders!N$1,Products!$A$1:$G$1,0)) -> 2.5 | O13: =INDEX(Products!$A$1:$G$49,MATCH(Orders!$G13,Products!$A$1:$A$49,0),MATCH(Orders!O$1,Products!$A$1:$G$1,0)) -> 34.155 | P13: =O13*H13 -> 170.775 | Q13: {=_xlfn.IFS(L13="Rob","Robusta",L13="Exc", "Excelsa",L13="Ara", "Arabica",L13="Lib", "Liberica")} -> Excelsa | R13: {=_xlfn.IFS(M13="M","Medium",M13="L","Light",M13="D","Dark")} -> Light
... A1001: IRV-20769-219 | B1001: 44119 | C1001: =YEAR(Orders_Table[[#This Row],[Order Date]]) -> 2020 | D1001: =MONTH(Orders_Table[[#This Row],[Order Date]]) -> 10 | E1001: {=_xlfn.IFS(Orders_Table[[#This Row],[Month Number]]=1,"Jan",Orders_Table[[#This Row],[Month Number]]=2,"Feb",Orders_Table[[#This Row],[Month Number]]=3,"Mar",Orders_Table[[#This Row],[Month Number]]=4,"Apr",Orders_Table[[#This Row],[Month Number]]=5,"May",Orders_Table[[#This Row],[Month Number]]=6,"Jun",Orders_Table[[#This Row],[Month Number]]=7,"Jul",Orders_Table[[#This Row],[Month Number]]=8,"Aug",Orders_Table[[#This Row],[Month Number]]=9,"Sep",Orders_Table[[#This Row],[Month Number]]=10,"Oct",Orders_Table[[#This Row],[Month Number]]=11,"Nov",Orders_Table[[#This Row],[Month Number]]=12,"Dec")} -> Oct | F1001: 77131-58092-GE | G1001: E-M-0.2 | H1001: 3 | I1001: {=_xlfn.XLOOKUP(F1001,Customers!A1000:$A$1001,Customers!B1000:$B$1001,"Not Found",0)} -> Vidovic Antonelli | J1001: {=IF(_xlfn.XLOOKUP(F1001,Customers!A1000:$A$1001,Customers!C1000:$C$1001,"Not Found",0)=0,"",_xlfn.XLOOKUP(F1001,Customers!A1000:$A$1001,Customers!C1000:$C$1001,"Not Found",0))} | K1001: {=_xlfn.XLOOKUP(F1001,Customers!A1000:$A$1001,Customers!G1000:$G$1001,"Not Found",0)} -> United Kingdom | L1001: =INDEX(Products!$A$1:$G$49,MATCH(Orders!$G1001,Products!$A$1:$A$49,0),MATCH(Orders!L$1,Products!$A$1:$G$1,0)) -> Exc | M1001: =INDEX(Products!$A$1:$G$49,MATCH(Orders!$G1001,Products!$A$1:$A$49,0),MATCH(Orders!M$1,Products!$A$1:$G$1,0)) -> M | N1001: =INDEX(Products!$A$1:$G$49,MATCH(Orders!$G1001,Products!$A$1:$A$49,0),MATCH(Orders!N$1,Products!$A$1:$G$1,0)) -> 0.2 | O1001: =INDEX(Products!$A$1:$G$49,MATCH(Orders!$G1001,Products!$A$1:$A$49,0),MATCH(Orders!O$1,Products!$A$1:$G$1,0)) -> 4.125 | P1001: =O1001*H1001 -> 12.375 | Q1001: {=_xlfn.IFS(L1001="Rob","Robusta",L1001="Exc", "Excelsa",L1001="Ara", "Arabica",L1001="Lib", "Liberica")} -> Excelsa | R1001: {=_xlfn.IFS(M1001="M","Medium",M1001="L","Light",M1001="D","Dark")} -> Medium

Sheet OrdersBackup
A1: Order ID | B1: Order Date | C1: Customer ID | D1: Product ID | E1: Quantity
A2: QEV-37451-860 | B2: 43713 | C2: 17670-51384-MA | D2: R-M-1 | E2: 2
A3: QEV-37451-860 | B3: 43713 | C3: 17670-51384-MA | D3: E-M-0.5 | E3: 5
A4: FAA-43335-268 | B4: 44364 | C4: 21125-22134-PX | D4: A-L-1 | E4: 1
A5: KAC-83089-793 | B5: 44392 | C5: 23806-46781-OU | D5: E-M-1 | E5: 2
A6: KAC-83089-793 | B6: 44392 | C6: 23806-46781-OU | D6: R-L-2.5 | E6: 2
A7: CVP-18956-553 | B7: 44412 | C7: 86561-91660-RB | D7: L-D-1 | E7: 3
A8: IPP-31994-879 | B8: 44582 | C8: 65223-29612-CB | D8: E-D-0.5 | E8: 3
A9: SNZ-65340-705 | B9: 44701 | C9: 21134-81676-FR | D9: L-L-0.2 | E9: 1
A10: EZT-46571-659 | B10: 43467 | C10: 03396-68805-ZC | D10: R-M-0.5 | E10: 3
A11: NWQ-70061-912 | B11: 43713 | C11: 61021-27840-ZN | D11: R-M-0.5 | E11: 1
A12: BKK-47233-845 | B12: 44263 | C12: 76239-90137-UQ | D12: A-D-1 | E12: 4
A13: VQR-01002-970 | B13: 44132 | C13: 49315-21985-BB | D13: E-L-2.5 | E13: 5
... A1001: IRV-20769-219 | B1001: 44119 | C1001: 77131-58092-GE | D1001: E-M-0.2 | E1001: 3

Sheet Customers
A1: Customer ID | B1: Customer Name | C1: Email | D1: Phone Number | E1: Address Line 1 | F1: City | G1: Country | H1: Postcode | I1: Loyalty Card
A2: 17670-51384-MA | B2: Aloisia Allner | C2: aallner0@lulu.com | D2: +1 (862) 817-0124 | E2: 57999 Pepper Wood Alley | F2: Paterson | G2: United States | H2: 7505 | I2: Yes
A3: 73342-18763-UW | B3: Piotr Bote | C3: pbote1@yelp.com | D3: +353 (913) 396-4653 | E3: 2112 Ridgeway Hill | F3: Crumlin | G3: Ireland | H3: D6W | I3: No
A4: 21125-22134-PX | B4: Jami Redholes | C4: jredholes2@tmall.com | D4: +1 (210) 986-6806 | E4: 5214 Bartillon Park | F4: San Antonio | G4: United States | H4: 78205 | I4: Yes
A5: 71253-00052-RN | B5: Dene Azema | C5: dazema3@facebook.com | D5: +1 (217) 418-0714 | E5: 27 Maywood Place | F5: Springfield | G5: United States | H5: 62711 | I5: Yes
A6: 23806-46781-OU | B6: Christoffer O' Shea | D6: +353 (698) 362-9201 | E6: 38980 Manitowish Junction | F6: Cill Airne | G6: Ireland | H6: N41 | I6: No
A7: 86561-91660-RB | B7: Beryle Cottier | D7: +1 (570) 289-7473 | E7: 2651 Stoughton Place | F7: Scranton | G7: United States | H7: 18505 | I7: No
A8: 65223-29612-CB | B8: Shaylynn Lobe | C8: slobe6@nifty.com | D8: +1 (937) 954-4541 | E8: 7005 Mariners Cove Place | F8: Dayton | G8: United States | H8: 45440 | I8: Yes
A9: 21134-81676-FR | B9: Melvin Wharfe | D9: +353 (507) 574-3034 | E9: 7 Straubel Road | F9: Kill | G9: Ireland | H9: P24 | I9: Yes
A10: 03396-68805-ZC | B10: Guthrey Petracci | C10: gpetracci8@livejournal.com | D10: +1 (310) 868-1842 | E10: 949 Paget Parkway | F10: Los Angeles | G10: United States | H10: 90045 | I10: No
A11: 61021-27840-ZN | B11: Rodger Raven | C11: rraven9@ed.gov | D11: +1 (213) 263-0288 | E11: 1 Reinke Avenue | F11: Los Angeles | G11: United States | H11: 90065 | I11: No
A12: 76239-90137-UQ | B12: Ferrell Ferber | C12: fferbera@businesswire.com | D12: +1 (408) 383-5302 | E12: 68 High Crossing Court | F12: San Jose | G12: United States | H12: 95160 | I12: No
A13: 49315-21985-BB | B13: Duky Phizackerly | C13: dphizackerlyb@utexas.edu | D13: +1 (408) 533-6012 | E13: 28643 Bluejay Crossing | F13: San Jose | G13: United States | H13: 95194 | I13: Yes
A14: 34136-36674-OM | B14: Rosaleen Scholar | C14: rscholarc@nyu.edu | D14: +1 (804) 420-0420 | E14: 80915 Montana Park | F14: Richmond | G14: United States | H14: 23285 | I14: No
A15: 39396-12890-PE | B15: Terence Vanyutin | C15: tvanyutind@wix.com | E15: 331 Bunting Hill | F15: Migrate | G15: United States | H15: 41905 | I15: No
A16: 95875-73336-RG | B16: Patrice Trobe | C16: ptrobee@wunderground.com | D16: +1 (314) 240-7896 | E16: 827 Declaration Plaza | F16: Saint Louis | G16: United States | H16: 63131 | I16: Yes
A17: 25473-43727-BY | B17: Llywellyn Oscroft | C17: loscroftf@ebay.co.uk | E17: 022 Roth Place | F17: Philadelphia | G17: United States | H17: 19172 | I17: No
A18: 99643-51048-IQ | B18: Minni Alabaster | C18: malabasterg@hexun.com | D18: +1 (971) 483-6255 | E18: 3 Charing Cross Trail | F18: Portland | G18: United States | H18: 97271 | I18: No
A19: 62173-15287-CU | B19: Rhianon Broxup | C19: rbroxuph@jimdo.com | D19: +1 (713) 663-1338 | E19: 83517 Thierer Court | F19: Houston | G19: United States | H19: 77240 | I19: No
A20: 57611-05522-ST | B20: Pall Redford | C20: predfordi@ow.ly | E20: 7337 Hayes Junction | F20: Caherconlish | G20: Ireland | H20: F45 | I20: Yes
A21: 76664-37050-DT | B21: Aurea Corradino | C21: acorradinoj@harvard.edu | D21: +1 (646) 202-5965 | E21: 698 Canary Terrace | F21: New York City | G21: United States | H21: 10060 | I21: Yes
A22: 84565-53984-SX | B22: Kendal Scardefield | D22: +353 (733) 405-3302 | E22: 3 Northridge Crossing | F22: Clondalkin | G22: Ireland | H22: D24 | I22: Yes
A23: 03090-88267-BQ | B23: Avrit Davidowsky | C23: adavidowskyl@netvibes.com | D23: +1 (616) 481-9962 | E23: 9 Warrior Junction | F23: Grand Rapids | G23: United States | H23: 49560 | I23: No
A24: 37651-47492-NC | B24: Annabel Antuk | C24: aantukm@kickstarter.com | D24: +1 (941) 740-6268 | E24: 77965 Lawn Park | F24: Punta Gorda | G24: United States | H24: 33982 | I24: Yes
A25: 95399-57205-HI | B25: Iorgo Kleinert | C25: ikleinertn@timesonline.co.uk | D25: +1 (360) 352-6598 | E25: 1 Morningstar Lane | F25: Vancouver | G25: United States | H25: 98682 | I25: Yes
A26: 24010-66714-HW | B26: Chrisy Blofeld | C26: cblofeldo@amazon.co.uk | D26: +1 (303) 936-3357 | E26: 013 Talisman Terrace | F26: Englewood | G26: United States | H26: 80150 | I26: No
A27: 07591-92789-UA | B27: Culley Farris | D27: +1 (941) 267-4822 | E27: 4 Mitchell Drive | F27: Punta Gorda | G27: United States | H27: 33982 | I27: Yes
A28: 49231-44455-IC | B28: Selene Shales | C28: sshalesq@umich.edu | D28: +1 (707) 881-5004 | E28: 74 Bultman Plaza | F28: Petaluma | G28: United States | H28: 94975 | I28: Yes
A29: 50124-88608-EO | B29: Vivie Danneil | C29: vdanneilr@mtv.com | D29: +353 (751) 346-0399 | E29: 5626 Darwin Avenue | F29: Tralee | G29: Ireland | H29: V92 | I29: No
A30: 00888-74814-UZ | B30: Theresita Newbury | C30: tnewburys@usda.gov | D30: +353 (803) 587-0026 | E30: 79526 Bultman Lane | F30: Clonskeagh | G30: Ireland | H30: D04 | I30: No
A31: 14158-30713-OB | B31: Mozelle Calcutt | C31: mcalcuttt@baidu.com | D31: +353 (928) 869-1762 | E31: 4389 Russell Way | F31: Rathwire | G31: Ireland | H31: Y25 | I31: Yes
A32: 51427-89175-QJ | B32: Adrian Swaine | D32: +1 (303) 486-9517 | E32: 95 Straubel Hill | F32: Aurora | G32: United States | H32: 80044 | I32: No
A33: 52082-49024-ON | B33: Ray Leivesley | C33: rleivesleyv@canalblog.com | D33: +1 (212) 535-7791 | E33: 91 Stephen Drive | F33: Jamaica | G33: United States | H33: 11407 | I33: No
A34: 04540-43685-DV | B34: Nelly Basezzi | C34: nbasezziw@webeden.co.uk | D34: +353 (125) 815-7345 | E34: 923 Mallard Junction | F34: Bailieborough | G34: Ireland | H34: C15 | I34: Yes
A35: 39123-12846-YJ | B35: Gallard Gatheral | C35: ggatheralx@123-reg.co.uk | E35: 40 Clemons Place | F35: Grand Forks | G35: United States | H35: 58207 | I35: No
A36: 44981-99666-XB | B36: Una Welberry | C36: uwelberryy@ebay.co.uk | D36: +44 (392) 503-8132 | E36: 40915 Schlimgen Park | F36: Upton | G36: United Kingdom | H36: DN21 | I36: Yes
A37: 24825-51803-CQ | B37: Faber Eilhart | C37: feilhartz@who.int | D37: +1 (304) 510-6095 | E37: 6966 Victoria Street | F37: Charleston | G37: United States | H37: 25362 | I37: No
A38: 77634-13918-GJ | B38: Zorina Ponting | C38: zponting10@altervista.org | D38: +1 (501) 172-1476 | E38: 7118 Holmberg Court | F38: Little Rock | G38: United States | H38: 72204 | I38: No
A39: 13694-25001-LX | B39: Silvio Strase | C39: sstrase11@booking.com | D39: +1 (303) 579-8015 | E39: 5 Forest Lane | F39: Denver | G39: United States | H39: 80291 | I39: No
A40: 08523-01791-TI | B40: Dorie de la Tremoille | C40: dde12@unesco.org | D40: +1 (612) 492-5160 | E40: 0817 Dennis Street | F40: Minneapolis | G40: United States | H40: 55458 | I40: No
...

Sheet Products
A1: Product ID | B1: Coffee Type | C1: Roast Type | D1: Size | E1: Unit Price | F1: Price per 100g | G1: Profit
A2: A-L-0.2 | B2: Ara | C2: L | D2: 0.2 | E2: 3.885 | F2: 1.9425 | G2: 0.34965
A3: A-L-0.5 | B3: Ara | C3: L | D3: 0.5 | E3: 7.77 | F3: 1.554 | G3: 0.6993
A4: A-L-1 | B4: Ara | C4: L | D4: 1 | E4: 12.95 | F4: 1.295 | G4: 1.1655
A5: A-L-2.5 | B5: Ara | C5: L | D5: 2.5 | E5: 29.785 | F5: 1.1914 | G5: 2.68065
A6: A-M-0.2 | B6: Ara | C6: M | D6: 0.2 | E6: 3.375 | F6: 1.6875 | G6: 0.30375
A7: A-M-0.5 | B7: Ara | C7: M | D7: 0.5 | E7: 6.75 | F7: 1.35 | G7: 0.6075
A8: A-M-1 | B8: Ara | C8: M | D8: 1 | E8: 11.25 | F8: 1.125 | G8: 1.0125
A9: A-M-2.5 | B9: Ara | C9: M | D9: 2.5 | E9: 25.875 | F9: 1.035 | G9: 2.32875
A10: A-D-0.2 | B10: Ara | C10: D | D10: 0.2 | E10: 2.985 | F10: 1.4925 | G10: 0.26865
A11: A-D-0.5 | B11: Ara | C11: D | D11: 0.5 | E11: 5.97 | F11: 1.194 | G11: 0.5373
A12: A-D-1 | B12: Ara | C12: D | D12: 1 | E12: 9.95 | F12: 0.995 | G12: 0.8955
A13: A-D-2.5 | B13: Ara | C13: D | D13: 2.5 | E13: 22.885 | F13: 0.9154 | G13: 2.05965
... A49: E-D-2.5 | B49: Exc | C49: D | D49: 2.5 | E49: 27.945 | F49: 1.1178 | G49: 3.07395
